{"date":"Thu Jun 06 2024 20:11:22 GMT+0400 (Azerbaijan Standard Time)","error":{"code":"ERR_UNHANDLED_REJECTION"},"exception":true,"level":"error","message":"uncaughtException: This error originated either by throwing inside of an async function without a catch block, or by rejecting a promise which was not handled with .catch(). The promise rejected with the reason \"My own error message\".\nUnhandledPromiseRejection: This error originated either by throwing inside of an async function without a catch block, or by rejecting a promise which was not handled with .catch(). The promise rejected with the reason \"My own error message\".","os":{"loadavg":[4.4970703125,4.2109375,3.8974609375],"uptime":620796},"process":{"argv":["/opt/homebrew/Cellar/node/21.7.2/bin/node","/Users/cemil/Desktop/CodeLandia/CM : MS - 003/Lesson codes/Level 3/Day 13/index.js"],"cwd":"/Users/cemil/Desktop/CodeLandia/CM : MS - 003/Lesson codes/Level 3/Day 13","execPath":"/opt/homebrew/Cellar/node/21.7.2/bin/node","gid":20,"memoryUsage":{"arrayBuffers":10515,"external":1480525,"heapTotal":9682944,"heapUsed":5591424,"rss":43237376},"pid":69426,"uid":501,"version":"v21.7.2"},"stack":"UnhandledPromiseRejection: This error originated either by throwing inside of an async function without a catch block, or by rejecting a promise which was not handled with .catch(). The promise rejected with the reason \"My own error message\".","trace":[]}
